Workbook

Sheet Assessment
A1: CYBERSECURITY ASSESSMENT QUESTIONNAIRE
A3: Instructions: Please answer all questions using the dropdown options. Your responses will be automatically scored.
A5: Category | B5: Question | C5: Response | D5: Score | E5: MAX
A6: COMPANY PROFILE
A7: COMPANY PROFILE | B7: "What is your primary business | organization model?" | C7: ALL 3 | D7: =IF(C7="Don't Know",5,IF(C7="All 3",5,IF(C7="B2G",4,IF(C7="B2B_B2C",4,IF(C7="B2B",2,IF(C7="B2C",1,0)))))) -> 5 | E7: =IF(C7="N/A",0,5) -> 5
A8: COMPANY PROFILE | B8: Do you consider your business |orgainzation as critical infrastructure? The essential systems and assets that impact national security, public health, or economic stability. | C8: No | D8: =IF(C8="No",3,IF(C8="N/A",0,IF(C8="Yes",5,IF(C8="Don't Know",5,)))) -> 3 | E8: =IF(C8="N/A",0,5) -> 5
A9: COMPANY PROFILE | B9: What is the range of employees/contractors working in your business |orgainzation? | C9: 0->9 | D9: =IF(C9="0->9",1,IF(C9="10->49",2,IF(C9="50->199",3,IF(C9="200->999",4,IF(C9="1000->4999",5,IF(C9="5000+",5,)))))) -> 1 | E9: =IF(C9="N/A",0,5) -> 5
A10: COMPANY PROFILE | B10: What is your annual revenue range? | C10: under 1M | D10: =IF(C10="Under 1M",1,IF(C10="1M - 10M",3,IF(C10="10M+",5,IF(C10="Don't Know",5,)))) -> 1 | E10: =IF(C10="N/A",0,5) -> 5
A11: COMPANY PROFILE | B11: Do you handle sensitive data (PII, PHI, financial, IP)? | C11: Yes | D11: =IF(C11="No",3,IF(C11="N/A",0,IF(C11="Yes",5,IF(C11="Don't Know",5,)))) -> 5 | E11: =IF(C11="N/A",0,5) -> 5
A12: COMPANY PROFILE | B12: Do you currently have a Cybersecurity Professional working with your business | orgainzation? | C12: Yes - In-House | D12: =IF(C12="No",3,IF(C12="N/A",0,IF(C12="Yes",5,IF(C12="Don't Know",5,)))) -> 0 | E12: =IF(C12="N/A",0,5) -> 5
A13: GOVERNANCE
A14: GOVERNANCE | B14: Do you have a formal cybersecurity policy in place? | C14: No | D14: =IF(C14="Yes",1,IF(C14="No",5,IF(C14="Don't Know",5,0))) -> 5 | E14: =IF(C14="N/A",0,5) -> 5
A15: GOVERNANCE | B15: Is cybersecurity oversight assigned to a specific role or leader? | C15: Yes | D15: =IF(C15="Yes",1,IF(C15="No",5,IF(C15="Don't Know",5,0))) -> 1 | E15: =IF(C15="N/A",0,5) -> 5
A16: GOVERNANCE | B16: Do you have a vendor/third-party risk management policy? | C16: No | D16: =IF(C16="Yes",1,IF(C16="No",5,IF(C16="Don't Know",5,0))) -> 5 | E16: =IF(C16="N/A",0,5) -> 5
A17: GOVERNANCE | B17: Are cybersecurity risks reported to executive leadership or the board? | C17: Yes | D17: =IF(C17="Yes",1,IF(C17="No",5,IF(C17="Don't Know",5,0))) -> 1 | E17: =IF(C17="N/A",0,5) -> 5
A18: GOVERNANCE | B18: Do you have a compliance requirement? (HIPAA, PCI-DSS, CMMC, SOC2, etc.) | C18: No | D18: =IF(C18="Yes",5,IF(C18="No",1,IF(C18="Don't Know",5,0))) -> 1 | E18: =IF(C18="N/A",0,5) -> 5
A19: GOVERNANCE | B19: Have you had a third-party security audit or assessment in the last 12 months? | C19: No | D19: =IF(C19="Yes",1,IF(C19="No",5,IF(C19="Don't Know",5,0))) -> 5 | E19: =IF(C19="N/A",0,5) -> 5
A20: IDENTIFY
A21: IDENTIFY | B21: Do you maintain an inventory of all hardware assets (computers, servers, mobile devices)? | C21: No | D21: =IF(C21="Yes",1,IF(C21="No",5,IF(C21="Don't Know",5,0))) -> 5 | E21: =IF(C21="N/A",0,5) -> 5
A22: IDENTIFY | B22: Do you maintain an inventory of all software and applications? | C22: Yes | D22: =IF(C22="Yes",1,IF(C22="No",5,IF(C22="Don't Know",5,0))) -> 1 | E22: =IF(C22="N/A",0,5) -> 5
A23: IDENTIFY | B23: Do you know which systems are most critical to your business operations? | C23: Yes | D23: =IF(C23="Yes",1,IF(C23="No",5,IF(C23="Don't Know",5,0))) -> 1 | E23: =IF(C23="N/A",0,5) -> 5
A24: IDENTIFY | B24: Do you have third-party vendors or partners involved in your operations? | C24: No | D24: =IF(C24="Yes",5,IF(C24="No",1,IF(C24="Don't Know",5,0))) -> 1 | E24: =IF(C24="N/A",0,5) -> 5
A25: IDENTIFY | B25: Do you know where all your sensitive data is stored and who has access to it? | C25: Yes | D25: =IF(C25="Yes",1,IF(C25="No",5,IF(C25="Don't Know",5,0))) -> 1 | E25: =IF(C25="N/A",0,5) -> 5
A26: PROTECT
A27: PROTECT | B27: Do you require multi-factor authentication (MFA) for accessing business systems? | C27: Yes | D27: =IF(C27="Yes",1,IF(C27="No",5,IF(C27="Don't Know",5,0))) -> 1 | E27: =IF(C27="N/A",0,5) -> 5
A28: PROTECT | B28: Are user access privileges reviewed and updated regularly? | C28: Yes | D28: =IF(C28="Yes",1,IF(C28="No",5,IF(C28="Don't Know",5,0))) -> 1 | E28: =IF(C28="N/A",0,5) -> 5
A29: PROTECT | B29: Do employees receive cybersecurity awareness training? | C29: No | D29: =IF(C29="Yes",1,IF(C29="No",5,IF(C29="Don't Know",5,0))) -> 5 | E29: =IF(C29="N/A",0,5) -> 5
A30: PROTECT | B30: Is sensitive data encrypted both at rest and in transit? | C30: No | D30: =IF(C30="Yes",1,IF(C30="No",5,IF(C30="Don't Know",5,0))) -> 5 | E30: =IF(C30="N/A",0,5) -> 5
A31: PROTECT | B31: Do you have a formal process for securely disposing of old devices and data? | C31: No | D31: =IF(C31="Yes",1,IF(C31="No",5,IF(C31="Don't Know",5,0))) -> 5 | E31: =IF(C31="N/A",0,5) -> 5
A32: DETECT
A33: DETECT | B33: Do you have security monitoring tools in place (antivirus, firewall, intrusion detection)? | C33: Yes | D33: =IF(C33="Yes",1,IF(C33="No",5,IF(C33="Don't Know",5,0))) -> 1 | E33: =IF(C33="N/A",0,5) -> 5
A34: DETECT | B34: Are system logs reviewed regularly for suspicious activity? | C34: No | D34: =IF(C34="Yes",1,IF(C34="No",5,IF(C34="Don't Know",5,0))) -> 5 | E34: =IF(C34="N/A",0,5) -> 5
A35: DETECT | B35: Do you receive alerts when unusual network activity occurs? | C35: No | D35: =IF(C35="Yes",1,IF(C35="No",5,IF(C35="Don't Know",5,0))) -> 5 | E35: =IF(C35="N/A",0,5) -> 5
A36: DETECT | B36: Are software and systems regularly scanned for vulnerabilities? | C36: No | D36: =IF(C36="Yes",1,IF(C36="No",5,IF(C36="Don't Know",5,0))) -> 5 | E36: =IF(C36="N/A",0,5) -> 5
A37: DETECT | B37: Do you have a process to detect unauthorized access attempts? | C37: No | D37: =IF(C37="Yes",1,IF(C37="No",5,IF(C37="Don't Know",5,0))) -> 5 | E37: =IF(C37="N/A",0,5) -> 5
A38: RESPOND
A39: RESPOND | B39: Do you have an incident response plan documented? | C39: No | D39: =IF(C39="Yes",1,IF(C39="No",5,IF(C39="Don't Know",5,0))) -> 5 | E39: =IF(C39="N/A",0,5) -> 5
A40: RESPOND | B40: Is there a designated team or person responsible for handling security incidents? | C40: Yes | D40: =IF(C40="Yes",1,IF(C40="No",5,IF(C40="Don't Know",5,0))) -> 1 | E40: =IF(C40="N/A",0,5) -> 5
A41: RESPOND | B41: Do you have a process to contain and mitigate security incidents? | C41: No | D41: =IF(C41="Yes",1,IF(C41="No",5,IF(C41="Don't Know",5,0))) -> 5 | E41: =IF(C41="N/A",0,5) -> 5
A42: RESPOND | B42: Are employees trained on how to report suspected security incidents? | C42: Yes | D42: =IF(C42="Yes",1,IF(C42="No",5,IF(C42="Don't Know",5,0))) -> 1 | E42: =IF(C42="N/A",0,5) -> 5
...

Sheet Results
A1: ASSESSMENT RESULTS & RISK ANALYSIS
A3: OVERALL RISK SCORE
B4: Operational Resilience | C4: Target Value
A5: Total Score: | B5: =SUMIF(Assessment!C21:C49,"<>N/A",Assessment!D21:D49) -> 65 | C5: =SUMIF(Assessment!C7:C12,"<>N/A",Assessment!D7:D12) -> 15
A6: Maximum Score: | B6: =SUMIF(Assessment!C14:C49,"<>N/A",Assessment!E14:E49) -> 155 | C6: =SUMIF(Assessment!C7:C12,"<>N/A",Assessment!E7:E12) -> 30
A7: Percentage: | B7: =TEXT(B5/B6,"0%")&" Risk Score" -> 42% Risk Score | C7: =TEXT(C5/C6,"0%")&" Risk Score" -> 50% Risk Score
A10: NIST FUNCTION BREAKDOWN
A12: NIST Function | B12: Score | C12: Max | D12: Status
A13: GOVERNANCE | B13: =SUM(Assessment!D14:D19) -> 18 | C13: =SUMIF(Assessment!D14:D19,"<>N/A",Assessment!E14:E19) -> 30 | D13: =IF(B13/25>=0.6,"🔴 Critical",IF(B13/25>=0.3,"🟡 Needs Improvement","🟢 Adequate")) -> 🔴 Critical
A14: IDENTIFY | B14: =SUM(Assessment!D21:D25) -> 9 | C14: =SUMIF(Assessment!D21:D25,"<>N/A",Assessment!E21:E25) -> 25 | D14: =IF(B14/25>=0.6,"🔴 Critical",IF(B14/25>=0.3,"🟡 Needs Improvement","🟢 Adequate")) -> 🟡 Needs Improvement
A15: PROTECT | B15: =SUM(Assessment!D27:D31) -> 17 | C15: =SUMIF(Assessment!D27:D31,"<>N/A",Assessment!E27:E31) -> 25 | D15: =IF(B15/25>=0.6,"🔴 Critical",IF(B15/25>=0.3,"🟡 Needs Improvement","🟢 Adequate")) -> 🔴 Critical
A16: DETECT | B16: =SUM(Assessment!D33:D37) -> 21 | C16: =SUMIF(Assessment!D33:D37,"<>N/A",Assessment!E33:E37) -> 25 | D16: =IF(B16/25>=0.6,"🔴 Critical",IF(B16/25>=0.3,"🟡 Needs Improvement","🟢 Adequate")) -> 🔴 Critical
A17: RESPOND | B17: =SUM(Assessment!D39:D43) -> 13 | C17: =SUMIF(Assessment!D39:D43,"<>N/A",Assessment!E39:E43) -> 25 | D17: =IF(B17/25>=0.6,"🔴 Critical",IF(B17/25>=0.3,"🟡 Needs Improvement","🟢 Adequate")) -> 🟡 Needs Improvement
A18: RECOVER | B18: =SUM(Assessment!D45:D49) -> 5 | C18: =SUMIF(Assessment!D39:D43,"<>N/A",Assessment!E39:E43) -> 25 | D18: =IF(B18/25>=0.6,"🔴 Critical",IF(B18/25>=0.3,"🟡 Needs Improvement","🟢 Adequate")) -> 🟢 Adequate
A21: RECOMMENDED ACTION
A23: Service Package: | B23: =IF(B5<=8,"Comprehensive Security Assessment + Remediation Package",IF(B5<=15,"Standard Security Assessment + Implementation Support",IF(B5<=20,"Focused Security Review + Enhancement Plan","Security Validation Review + Ongoing Support Services"))) -> Security Validation Review + Ongoing Support Services
A25: See the Dashboard tab for your full risk assessment and recommended actions. Based on your score, detailed recommendations will be provided during your consultation.

Sheet Dashboard
A1: CYBERSECURITY ASSESSMENT DASHBOARD
A3: OVERALL RISK SCORE | F3: Risk Distribution
A4: =Results!B5 -> 65 | D4: =Results!C5 -> 15
A5: =Results!B7 -> 42% Risk Score | D5: =Results!C7 -> 50% Risk Score
A6: Operational Resilience | D6: Target Value
A8: NIST FUNCTION PERFORMANCE
A9: Function | B9: Your Score | C9: Maximum | D9: Gap
A10: GOVERNANCE | B10: =Results!B13 -> 18 | C10: =Results!C13 -> 30 | D10: =C10-B10 -> 12
A11: IDENTIFY | B11: =Results!B14 -> 9 | C11: =Results!C14 -> 25 | D11: =C11-B11 -> 16
A12: PROTECT | B12: =Results!B15 -> 17 | C12: =Results!C15 -> 25 | D12: =C12-B12 -> 8
A13: DETECT | B13: =Results!B16 -> 21 | C13: =Results!C16 -> 25 | D13: =C13-B13 -> 4
A14: RESPOND | B14: =Results!B17 -> 13 | C14: =Results!C17 -> 25 | D14: =C14-B14 -> 12
A15: RECOVER | B15: =Results!B18 -> 5 | C15: =Results!C18 -> 25 | D15: =C15-B15 -> 20
H21: KEY INSIGHTS
H23: Weakest Function: | I23: =INDEX(Dashboard!$A$11:$A$15,MATCH(MIN(Dashboard!$B$11:$B$15),Dashboard!$B$11:$B$15,0)) -> RECOVER
E24: Achieved | F24: =Results!B5 -> 65 | H24: Strongest Function: | I24: =INDEX(Dashboard!$A$11:$A$15,MATCH(MAX(Dashboard!$B$11:$B$15),Dashboard!$B$11:$B$15,0)) -> DETECT
E25: Remaining | F25: =25-Results!B5 -> -40
H26: Total Functions Below 3.5: | I26: =COUNTIF(Dashboard!$B$11:$B$15,"<3.5") -> 0
